Workbook

Sheet EV Charging
A1: Date | B1: Vehicle | C1: ODO | D1: Current Charge Remaining | E1: Target Charge | F1: Charge Needed to Target | G1: in KwH | H1: Charger used | I1: Time needed (E / F) | J1: Time start | K1: Est time end | L1: Actual time end | M1: Actual Charge | N1: Actual Charged | O1: in KwH 2 | P1: Actual Charging Time | Q1: Actual Charge Rate | R1: Location | S1: Cost of Charging | T1: Km / KwH | U1: Kms driven from last recharge | V1: # of days from last recharge
A2: 45861 | B2: BYD Atto3 | D2: 0.35 | E2: 0.8 | F2: =E2-D2 -> 0.45 | G2: =F2*VLOOKUP(B2,EVs!$A$2:$E$5,2,false) -> 27.225 | H2: 1.9 Kw | I2: =G2/left(H2,3) -> 14.328947 | J2: 45861.781 | K2: =J2+I2/24 -> 45862.378 | L2: 45862.393 | M2: 0.81 | N2: =M2-D2 -> 0.46 | O2: =N2*VLOOKUP(B2,EVs!$A$2:$E$5,2,false) -> 27.83 | P2: =(L2-J2)*24 -> 14.683333 | Q2: =N2*VLOOKUP(B2,EVs!$A$2:$E$5,2,false)/P2 -> 1.8953462 | R2: Garage | S2: =O2*15 -> 417.45
A3: 45866 | B3: BYD Atto3 | D3: 0.49 | H3: 7 Kw | J3: 45866.424 | L3: 45866.458 | M3: 0.54 | N3: =M3-D3 -> 0.05 | O3: =N3*VLOOKUP(B3,EVs!$A$2:$E$5,2,false) -> 3.025 | P3: =(L3-J3)*24 -> 0.81666667 | Q3: =N3*VLOOKUP(B3,EVs!$A$2:$E$5,2,false)/P3 -> 3.7040816 | R3: Dela Rosa Car Park | S3: =O3*28 -> 84.7
A4: 45871 | B4: BYD Atto3 | D4: 0.21 | E4: 0.8 | F4: =E4-D4 -> 0.59 | G4: =F4*VLOOKUP(B4,EVs!$A$2:$E$5,2,false) -> 35.695 | H4: 1.9 Kw | I4: =G4/left(H4,3) -> 18.786842 | J4: 45871.813 | K4: =J4+I4/24 -> 45872.596 | L4: 45872.618 | M4: 0.8 | N4: =M4-D4 -> 0.59 | O4: =N4*VLOOKUP(B4,EVs!$A$2:$E$5,2,false) -> 35.695 | P4: =(L4-J4)*24 -> 19.316667 | Q4: =N4*VLOOKUP(B4,EVs!$A$2:$E$5,2,false)/P4 -> 1.8478861 | R4: Garage | S4: =O4*15 -> 535.425
A5: 45878 | B5: BYD Atto3 | D5: 0.49 | E5: 0.8 | F5: =E5-D5 -> 0.31 | G5: =F5*VLOOKUP(B5,EVs!$A$2:$E$5,2,false) -> 18.755 | H5: 7.0 Kw | I5: =G5/left(H5,3) -> 2.6792857 | J5: 45878.461 | K5: =J5+I5/24 -> 45878.573 | L5: 45878.589 | M5: 0.8 | N5: =M5-D5 -> 0.31 | O5: =N5*VLOOKUP(B5,EVs!$A$2:$E$5,2,false) -> 18.755 | P5: =(L5-J5)*24 -> 3.0666667 | Q5: =N5*VLOOKUP(B5,EVs!$A$2:$E$5,2,false)/P5 -> 6.1157609 | R5: Garage | S5: =O5*15 -> 281.325
A6: 45885 | B6: BYD Atto3 | D6: 0.32 | E6: 0.8 | F6: =E6-D6 -> 0.48 | G6: =F6*VLOOKUP(B6,EVs!$A$2:$E$5,2,false) -> 29.04 | H6: 6.4 Kw | I6: =G6/left(H6,3) -> 4.5375 | J6: 45885.812 | K6: =J6+I6/24 -> 45886.001 | L6: 45886.01 | M6: 0.8 | N6: =M6-D6 -> 0.48 | O6: =N6*VLOOKUP(B6,EVs!$A$2:$E$5,2,false) -> 29.04 | P6: =(L6-J6)*24 -> 4.7541667 | Q6: =N6*VLOOKUP(B6,EVs!$A$2:$E$5,2,false)/P6 -> 6.108326 | R6: Garage | S6: =O6*15 -> 435.6
A7: 45896 | B7: BYD Atto3 | D7: 0.23 | E7: 0.5 | F7: =E7-D7 -> 0.27 | G7: =F7*VLOOKUP(B7,EVs!$A$2:$E$5,2,false) -> 16.335 | H7: 6.1 Kw | I7: =G7/left(H7,3) -> 2.6778689 | J7: 45896.681 | K7: =J7+I7/24 -> 45896.792 | L7: 45896.745 | M7: 0.39 | N7: =M7-D7 -> 0.16 | O7: =N7*VLOOKUP(B7,EVs!$A$2:$E$5,2,false) -> 9.68 | P7: =(L7-J7)*24 -> 1.55 | Q7: =N7*VLOOKUP(B7,EVs!$A$2:$E$5,2,false)/P7 -> 6.2451613 | R7: Garage | S7: =O7*15 -> 145.2
A8: 45897 | B8: BYD Atto3 | D8: 0.38 | E8: 1 | F8: =E8-D8 -> 0.62 | G8: =F8*VLOOKUP(B8,EVs!$A$2:$E$5,2,false) -> 37.51 | H8: 6.1 Kw | I8: =G8/left(H8,3) -> 6.1491803 | J8: 45897.264 | K8: =J8+I8/24 -> 45897.52 | L8: 45897.53 | M8: 0.99 | N8: =M8-D8 -> 0.61 | O8: =N8*VLOOKUP(B8,EVs!$A$2:$E$5,2,false) -> 36.905 | P8: =(L8-J8)*24 -> 6.3833333 | Q8: =N8*VLOOKUP(B8,EVs!$A$2:$E$5,2,false)/P8 -> 5.7814621 | R8: Garage | S8: =O8*15 -> 553.575
A9: 45904 | B9: BYD Atto3 | D9: 0.48 | E9: 0.8 | F9: =E9-D9 -> 0.32 | G9: =F9*VLOOKUP(B9,EVs!$A$2:$E$5,2,false) -> 19.36 | H9: 24 Kw | I9: =G9/left(H9,3) -> 0.80666667 | J9: 45904.487 | K9: =J9+I9/24 -> 45904.52 | L9: 45904.519 | M9: 0.79 | N9: =M9-D9 -> 0.31 | O9: =N9*VLOOKUP(B9,EVs!$A$2:$E$5,2,false) -> 18.755 | P9: =(L9-J9)*24 -> 0.78333333 | Q9: =N9*VLOOKUP(B9,EVs!$A$2:$E$5,2,false)/P9 -> 23.942553 | R9: UP Town | S9: =O9*32 -> 600.16
A10: 45909 | B10: BYD Atto3 | D10: 0.25 | E10: 0.8 | F10: =E10-D10 -> 0.55 | G10: =F10*VLOOKUP(B10,EVs!$A$2:$E$5,2,false) -> 33.275 | H10: 6.1 Kw | I10: =G10/left(H10,3) -> 5.454918 | J10: 45909.004 | K10: =J10+I10/24 -> 45909.231 | L10: 45909.259 | M10: 0.87 | N10: =M10-D10 -> 0.62 | O10: =N10*VLOOKUP(B10,EVs!$A$2:$E$5,2,false) -> 37.51 | P10: =(L10-J10)*24 -> 6.1166667 | Q10: =N10*VLOOKUP(B10,EVs!$A$2:$E$5,2,false)/P10 -> 6.1324251 | R10: Garage | S10: =O10*15 -> 562.65
A11: 45920 | B11: BYD Atto3 | D11: 0.27 | E11: 0.8 | F11: =E11-D11 -> 0.53 | G11: =F11*VLOOKUP(B11,EVs!$A$2:$E$5,2,false) -> 32.065 | H11: 6.1 Kw | I11: =G11/left(H11,3) -> 5.2565574 | J11: 45920.342 | K11: =J11+I11/24 -> 45920.561 | L11: 45920.574 | M11: 0.82 | N11: =M11-D11 -> 0.55 | O11: =N11*VLOOKUP(B11,EVs!$A$2:$E$5,2,false) -> 33.275 | P11: =(L11-J11)*24 -> 5.5666667 | Q11: =N11*VLOOKUP(B11,EVs!$A$2:$E$5,2,false)/P11 -> 5.9775449 | R11: Garage | S11: =O11*15 -> 499.125
A12: 45926 | B12: BYD Atto3 | D12: 0.27 | E12: 0.8 | F12: =E12-D12 -> 0.53 | G12: =F12*VLOOKUP(B12,EVs!$A$2:$E$5,2,false) -> 32.065 | H12: 6.1 Kw | I12: =G12/left(H12,3) -> 5.2565574 | J12: 45926.569 | K12: =J12+I12/24 -> 45926.788 | L12: 45926.828 | M12: 0.89 | N12: =M12-D12 -> 0.62 | O12: =N12*VLOOKUP(B12,EVs!$A$2:$E$5,2,false) -> 37.51 | P12: =(L12-J12)*24 -> 6.2166667 | Q12: =N12*VLOOKUP(B12,EVs!$A$2:$E$5,2,false)/P12 -> 6.0337802 | R12: Garage | S12: =O12*15 -> 562.65
A13: 45934 | B13: BYD Atto3 | D13: 0.18 | E13: 1 | F13: =E13-D13 -> 0.82 | G13: =F13*VLOOKUP(B13,EVs!$A$2:$E$5,2,false) -> 49.61 | H13: 6.1 Kw | I13: =G13/left(H13,3) -> 8.1327869 | J13: 45934.821 | K13: =J13+I13/24 -> 45935.16 | L13: 45935.149 | M13: 1 | N13: =M13-D13 -> 0.82 | O13: =N13*VLOOKUP(B13,EVs!$A$2:$E$5,2,false) -> 49.61 | P13: =(L13-J13)*24 -> 7.8666667 | Q13: =N13*VLOOKUP(B13,EVs!$A$2:$E$5,2,false)/P13 -> 6.3063559 | R13: Garage | S13: =O13*15 -> 744.15
A14: 45945 | B14: BYD Atto3 | D14: 0.35 | E14: 0.8 | F14: =E14-D14 -> 0.45 | G14: =F14*VLOOKUP(B14,EVs!$A$2:$E$5,2,false) -> 27.225 | H14: 6.1 Kw | I14: =G14/left(H14,3) -> 4.4631148 | J14: 45945.45 | K14: =J14+I14/24 -> 45945.636 | L14: 45945.65 | M14: 0.82 | N14: =M14-D14 -> 0.47 | O14: =N14*VLOOKUP(B14,EVs!$A$2:$E$5,2,false) -> 28.435 | P14: =(L14-J14)*24 -> 4.8041667 | Q14: =N14*VLOOKUP(B14,EVs!$A$2:$E$5,2,false)/P14 -> 5.9188205 | R14: Garage | S14: =O14*15 -> 426.525
A15: 45950 | B15: BYD Atto3 | D15: 0.15 | E15: 1 | F15: =E15-D15 -> 0.85 | G15: =F15*VLOOKUP(B15,EVs!$A$2:$E$5,2,false) -> 51.425 | H15: 6.1 Kw | I15: =G15/left(H15,3) -> 8.4303279 | J15: 45950.822 | K15: =J15+I15/24 -> 45951.173 | L15: 45951.158 | M15: 1 | N15: =M15-D15 -> 0.85 | O15: =N15*VLOOKUP(B15,EVs!$A$2:$E$5,2,false) -> 51.425 | P15: =(L15-J15)*24 -> 8.0833333 | Q15: =N15*VLOOKUP(B15,EVs!$A$2:$E$5,2,false)/P15 -> 6.3618557 | R15: Garage | S15: =O15*15 -> 771.375
A16: 45953 | B16: BYD Atto3 | E16: PMS | J16: 45953.375 | L16: 45953.458 | R16: Hexagon
A17: 45959 | B17: BYD Atto3 | D17: 0.27 | E17: 0.8 | F17: =E17-D17 -> 0.53 | G17: =F17*VLOOKUP(B17,EVs!$A$2:$E$5,2,false) -> 32.065 | H17: 6.1 Kw | I17: =G17/left(H17,3) -> 5.2565574 | J17: 45959.946 | K17: =J17+I17/24 -> 45960.165 | L17: 45960.167 | M17: 0.8 | N17: =M17-D17 -> 0.53 | O17: =N17*VLOOKUP(B17,EVs!$A$2:$E$5,2,false) -> 32.065 | P17: =(L17-J17)*24 -> 5.3 | Q17: =N17*VLOOKUP(B17,EVs!$A$2:$E$5,2,false)/P17 -> 6.05 | R17: Garage | S17: =O17*15 -> 480.975
A18: 45967 | B18: BYD Atto3 | D18: 0.29 | E18: 0.8 | F18: =E18-D18 -> 0.51 | G18: =F18*VLOOKUP(B18,EVs!$A$2:$E$5,2,false) -> 30.855 | H18: 6.1 Kw | I18: =G18/left(H18,3) -> 5.0581967 | J18: 45967.82 | K18: =J18+I18/24 -> 45968.031 | L18: 45968.037 | M18: 0.82 | N18: =M18-D18 -> 0.53 | O18: =N18*VLOOKUP(B18,EVs!$A$2:$E$5,2,false) -> 32.065 | P18: =(L18-J18)*24 -> 5.2166667 | Q18: =N18*VLOOKUP(B18,EVs!$A$2:$E$5,2,false)/P18 -> 6.1466454 | R18: Garage | S18: =O18*15 -> 480.975
A19: 45975 | B19: BYD Atto3 | C19: 2550 | D19: 0.31 | E19: 1 | F19: =E19-D19 -> 0.69 | G19: =F19*VLOOKUP(B19,EVs!$A$2:$E$5,2,false) -> 41.745 | H19: 6.1 Kw | I19: =G19/left(H19,3) -> 6.8434426 | J19: 45975.89 | K19: =J19+I19/24 -> 45976.175 | L19: 45976.176 | M19: 1 | N19: =M19-D19 -> 0.69 | O19: =N19*VLOOKUP(B19,EVs!$A$2:$E$5,2,false) -> 41.745 | P19: =(L19-J19)*24 -> 6.8666667 | Q19: =N19*VLOOKUP(B19,EVs!$A$2:$E$5,2,false)/P19 -> 6.0793689 | R19: Garage | S19: =O19*15 -> 626.175
A20: 45988 | B20: BYD Atto3 | D20: 0.4 | E20: 1 | F20: =E20-D20 -> 0.6 | G20: =F20*VLOOKUP(B20,EVs!$A$2:$E$5,2,false) -> 36.3 | H20: 6.1 Kw | I20: =G20/left(H20,3) -> 5.9508197 | J20: 45988.829 | K20: =J20+I20/24 -> 45989.077 | L20: 45989.084 | M20: 1 | N20: =M20-D20 -> 0.6 | O20: =N20*VLOOKUP(B20,EVs!$A$2:$E$5,2,false) -> 36.3 | P20: =(L20-J20)*24 -> 6.1166667 | Q20: =N20*VLOOKUP(B20,EVs!$A$2:$E$5,2,false)/P20 -> 5.9346049 | R20: Garage | S20: =O20*15 -> 544.5
A21: 45990 | B21: BYD Atto3 | D21: 0.4 | E21: 0.65 | F21: =E21-D21 -> 0.25 | G21: =F21*VLOOKUP(B21,EVs!$A$2:$E$5,2,false) -> 15.125 | H21: 6.1 Kw | I21: =G21/left(H21,3) -> 2.4795082 | J21: 45990.653 | K21: =J21+I21/24 -> 45990.757 | L21: 45990.767 | M21: 0.67 | N21: =M21-D21 -> 0.27 | O21: =N21*VLOOKUP(B21,EVs!$A$2:$E$5,2,false) -> 16.335 | P21: =(L21-J21)*24 -> 2.7333333 | Q21: =N21*VLOOKUP(B21,EVs!$A$2:$E$5,2,false)/P21 -> 5.9762195 | R21: Garage | S21: =O21*15 -> 245.025
A22: 45995 | B22: BYD Atto3 | D22: 0.25 | E22: 0.8 | F22: =E22-D22 -> 0.55 | G22: =F22*VLOOKUP(B22,EVs!$A$2:$E$5,2,false) -> 33.275 | H22: 6.1 Kw | I22: =G22/left(H22,3) -> 5.454918 | J22: 45995.426 | K22: =J22+I22/24 -> 45995.653 | L22: 45995.653 | M22: 0.8 | N22: =M22-D22 -> 0.55 | O22: =N22*VLOOKUP(B22,EVs!$A$2:$E$5,2,false) -> 33.275 | P22: =(L22-J22)*24 -> 5.45 | Q22: =N22*VLOOKUP(B22,EVs!$A$2:$E$5,2,false)/P22 -> 6.1055046 | R22: Garage | S22: =O22*15 -> 499.125
A23: 46002 | B23: BYD Atto3 | D23: 0.31 | E23: 0.36 | F23: =E23-D23 -> 0.05 | G23: =F23*VLOOKUP(B23,EVs!$A$2:$E$5,2,false) -> 3.025 | H23: 6.1 Kw | I23: =G23/left(H23,3) -> 0.49590164 | J23: 46002.72 | K23: =J23+I23/24 -> 46002.741 | L23: 46002.738 | M23: 0.36 | N23: =M23-D23 -> 0.05 | O23: =N23*VLOOKUP(B23,EVs!$A$2:$E$5,2,false) -> 3.025 | P23: =(L23-J23)*24 -> 0.43333333 | Q23: =N23*VLOOKUP(B23,EVs!$A$2:$E$5,2,false)/P23 -> 6.9807692 | R23: Garage | S23: =O23*15 -> 45.375
A24: 46002 | B24: BYD Atto3 | D24: 0.28 | E24: 0.8 | F24: =E24-D24 -> 0.52 | G24: =F24*VLOOKUP(B24,EVs!$A$2:$E$5,2,false) -> 31.46 | H24: 6.1 Kw | I24: =G24/left(H24,3) -> 5.157377 | J24: 46002.946 | K24: =J24+I24/24 -> 46003.161 | L24: 46003.161 | M24: 0.8 | N24: =M24-D24 -> 0.52 | O24: =N24*VLOOKUP(B24,EVs!$A$2:$E$5,2,false) -> 31.46 | P24: =(L24-J24)*24 -> 5.157377 | Q24: =N24*VLOOKUP(B24,EVs!$A$2:$E$5,2,false)/P24 -> 6.1 | R24: Garage | S24: =O24*15 -> 471.9
A25: 46014 | B25: BYD Atto3 | C25: 3500 | D25: 0.28 | E25: 0.56 | F25: =E25-D25 -> 0.28 | G25: =F25*VLOOKUP(B25,EVs!$A$2:$E$5,2,false) -> 16.94 | H25: 6.1 Kw | I25: =G25/left(H25,3) -> 2.7770492 | J25: 46014.348 | K25: =J25+I25/24 -> 46014.464 | L25: 46014.467 | M25: 0.56 | N25: =M25-D25 -> 0.28 | O25: =N25*VLOOKUP(B25,EVs!$A$2:$E$5,2,false) -> 16.94 | P25: =(L25-J25)*24 -> 2.85 | Q25: =N25*VLOOKUP(B25,EVs!$A$2:$E$5,2,false)/P25 -> 5.9438596 | R25: Garage | S25: =O25*15 -> 254.1
A26: 46014 | B26: BYD Atto3 | C26: 3519 | D26: 0.49 | E26: 1 | F26: =E26-D26 -> 0.51 | G26: =F26*VLOOKUP(B26,EVs!$A$2:$E$5,2,false) -> 30.855 | H26: 6.1 Kw | I26: =G26/left(H26,3) -> 5.0581967 | J26: 46014.667 | K26: =J26+I26/24 -> 46014.877 | L26: 46014.876 | M26: 1 | N26: =M26-D26 -> 0.51 | O26: =N26*VLOOKUP(B26,EVs!$A$2:$E$5,2,false) -> 30.855 | P26: =(L26-J26)*24 -> 5.0333333 | Q26: =N26*VLOOKUP(B26,EVs!$A$2:$E$5,2,false)/P26 -> 6.1301324 | R26: Garage | S26: =O26*15 -> 462.825
A27: 46022 | B27: BYD Atto3 | C27: 3708 | D27: 0.4 | E27: 1 | F27: =E27-D27 -> 0.6 | G27: =F27*VLOOKUP(B27,EVs!$A$2:$E$5,2,false) -> 36.3 | H27: 6.1 Kw | I27: =G27/left(H27,3) -> 5.9508197 | J27: 46022.992 | K27: =J27+I27/24 -> 46023.24 | L27: 46023.252 | M27: 1 | N27: =M27-D27 -> 0.6 | O27: =N27*VLOOKUP(B27,EVs!$A$2:$E$5,2,false) -> 36.3 | P27: =(L27-J27)*24 -> 6.25 | Q27: =N27*VLOOKUP(B27,EVs!$A$2:$E$5,2,false)/P27 -> 5.808 | R27: Garage | S27: =O27*15 -> 544.5 | T27: =(C27-C26)/((M26-D27)*60.5) -> 5.2066116 | U27: =C27-C26 -> 189 | V27: =A27-A26 -> 8
A28: 46028 | B28: BYD Atto3 | C28: 3985 | D28: 0.29 | E28: 0.8 | F28: =E28-D28 -> 0.51 | G28: =F28*VLOOKUP(B28,EVs!$A$2:$E$5,2,false) -> 30.855 | H28: 6.1 Kw | I28: =G28/left(H28,3) -> 5.0581967 | J28: 46028.833 | K28: =J28+I28/24 -> 46029.043 | L28: 46029.063 | M28: 0.85 | N28: =M28-D28 -> 0.56 | O28: =N28*VLOOKUP(B28,EVs!$A$2:$E$5,2,false) -> 33.88 | P28: =(L28-J28)*24 -> 5.5333333 | Q28: =N28*VLOOKUP(B28,EVs!$A$2:$E$5,2,false)/P28 -> 6.1228916 | R28: Garage | S28: =O28*15 -> 508.2 | T28: =(C28-C27)/((M27-D28)*60.5) -> 6.448609 | U28: =C28-C27 -> 277 | V28: =A28-A27 -> 6
A29: 46037 | B29: BYD Atto3 | C29: 4193 | D29: 0.23 | E29: 0.8 | F29: =E29-D29 -> 0.57 | G29: =F29*VLOOKUP(B29,EVs!$A$2:$E$5,2,false) -> 34.485 | H29: 6.1 Kw | I29: =G29/left(H29,3) -> 5.6532787 | J29: 46037.484 | K29: =J29+I29/24 -> 46037.72 | L29: 46037.722 | M29: 0.81 | N29: =M29-D29 -> 0.58 | O29: =N29*VLOOKUP(B29,EVs!$A$2:$E$5,2,false) -> 35.09 | P29: =(L29-J29)*24 -> 5.7166667 | Q29: =N29*VLOOKUP(B29,EVs!$A$2:$E$5,2,false)/P29 -> 6.1381924 | R29: Garage | S29: =O29*15 -> 526.35 | T29: =(C29-C28)/((M28-D29)*60.5) -> 5.5451879 | U29: =C29-C28 -> 208 | V29: =A29-A28 -> 9
A30: 46049 | B30: BYD Atto3 | C30: 4364 | D30: 0.26 | E30: 0.93 | F30: =E30-D30 -> 0.67 | G30: =F30*VLOOKUP(B30,EVs!$A$2:$E$5,2,false) -> 40.535 | H30: 6.1 Kw | I30: =G30/left(H30,3) -> 6.645082 | J30: 46049.538 | K30: =J30+I30/24 -> 46049.815 | L30: 46049.824 | M30: 0.93 | N30: =M30-D30 -> 0.67 | O30: =N30*VLOOKUP(B30,EVs!$A$2:$E$5,2,false) -> 40.535 | P30: =(L30-J30)*24 -> 6.85 | Q30: =N30*VLOOKUP(B30,EVs!$A$2:$E$5,2,false)/P30 -> 5.9175182 | R30: Garage | S30: =O30*15 -> 608.025 | T30: =(C30-C29)/((M29-D30)*60.5) -> 5.1389932 | U30: =C30-C29 -> 171 | V30: =A30-A29 -> 12
A31: 46063 | B31: BYD Atto3 | C31: 4573 | D31: 0.25 | E31: 0.72 | F31: =E31-D31 -> 0.47 | G31: =F31*VLOOKUP(B31,EVs!$A$2:$E$5,2,false) -> 28.435 | H31: 6.1 Kw | I31: =G31/left(H31,3) -> 4.6614754 | J31: 46063.617 | K31: =J31+I31/24 -> 46063.812 | L31: 46063.812 | M31: 0.72 | N31: =M31-D31 -> 0.47 | O31: =N31*VLOOKUP(B31,EVs!$A$2:$E$5,2,false) -> 28.435 | P31: =(L31-J31)*24 -> 4.6666667 | Q31: =N31*VLOOKUP(B31,EVs!$A$2:$E$5,2,false)/P31 -> 6.0932143 | R31: Garage | S31: =O31*15 -> 426.525 | T31: =(C31-C30)/((M30-D31)*60.5) -> 5.0802139 | U31: =C31-C30 -> 209 | V31: =A31-A30 -> 14
A32: 46063 | B32: BYD Atto3 | C32: 4581 | D32: 0.7 | E32: 0.81 | F32: =E32-D32 -> 0.11 | G32: =F32*VLOOKUP(B32,EVs!$A$2:$E$5,2,false) -> 6.655 | H32: 6.1 Kw | I32: =G32/left(H32,3) -> 1.0909836 | J32: 46063.835 | K32: =J32+I32/24 -> 46063.88 | L32: 46063.881 | M32: 0.81 | N32: =M32-D32 -> 0.11 | O32: =N32*VLOOKUP(B32,EVs!$A$2:$E$5,2,false) -> 6.655 | P32: =(L32-J32)*24 -> 1.1166667 | Q32: =N32*VLOOKUP(B32,EVs!$A$2:$E$5,2,false)/P32 -> 5.9597015 | R32: Garage | S32: =O32*15 -> 99.825 | T32: =(C32-C31)/((M31-D32)*60.5) -> 6.6115702 | U32: =C32-C31 -> 8 | V32: =A32-A31 -> 0
A33: 46069 | B33: BYD Atto3 | C33: 4760 | D33: 0.24 | E33: 1 | F33: =E33-D33 -> 0.76 | G33: =F33*VLOOKUP(B33,EVs!$A$2:$E$5,2,false) -> 45.98 | H33: 6.1 Kw | I33: =G33/left(H33,3) -> 7.5377049 | J33: 46069.713 | K33: =J33+I33/24 -> 46070.027 | L33: 46070.028 | M33: 1 | N33: =M33-D33 -> 0.76 | O33: =N33*VLOOKUP(B33,EVs!$A$2:$E$5,2,false) -> 45.98 | P33: =(L33-J33)*24 -> 7.5666667 | Q33: =N33*VLOOKUP(B33,EVs!$A$2:$E$5,2,false)/P33 -> 6.076652 | R33: Garage | S33: =O33*15 -> 689.7 | T33: =(C33-C32)/((M32-D33)*60.5) -> 5.1906626 | U33: =C33-C32 -> 179 | V33: =A33-A32 -> 6
A34: 46083 | B34: BYD Atto3 | C34: 5000 | D34: 0.2 | E34: 0.81 | F34: =E34-D34 -> 0.61 | G34: =F34*VLOOKUP(B34,EVs!$A$2:$E$5,2,false) -> 36.905 | H34: 6.1 Kw | I34: =G34/left(H34,3) -> 6.05 | J34: 46083.74 | K34: =J34+I34/24 -> 46083.992 | L34: 46083.992 | M34: 0.81 | N34: =M34-D34 -> 0.61 | O34: =N34*VLOOKUP(B34,EVs!$A$2:$E$5,2,false) -> 36.905 | P34: =(L34-J34)*24 -> 6.0333333 | Q34: =N34*VLOOKUP(B34,EVs!$A$2:$E$5,2,false)/P34 -> 6.1168508 | R34: Garage | S34: =O34*15 -> 553.575 | T34: =(C34-C33)/((M33-D34)*60.5) -> 4.9586777 | U34: =C34-C33 -> 240 | V34: =A34-A33 -> 14 | W34: *eff went down probably bec i left the car running n the mall for 30-40mins.
A35: 46092 | B35: BYD Atto3 | C35: 5177 | D35: 0.22 | E35: 0.89 | F35: =E35-D35 -> 0.67 | G35: =F35*VLOOKUP(B35,EVs!$A$2:$E$5,2,false) -> 40.535 | H35: 6.1 Kw | I35: =G35/left(H35,3) -> 6.645082 | J35: 46092.503 | K35: =J35+I35/24 -> 46092.78 | L35: 46092.783 | M35: 0.89 | N35: =M35-D35 -> 0.67 | O35: =N35*VLOOKUP(B35,EVs!$A$2:$E$5,2,false) -> 40.535 | P35: =(L35-J35)*24 -> 6.7 | Q35: =N35*VLOOKUP(B35,EVs!$A$2:$E$5,2,false)/P35 -> 6.05 | R35: Garage | S35: =O35*15 -> 608.025 | T35: =(C35-C34)/((M34-D35)*60.5) -> 4.9586777 | U35: =C35-C34 -> 177 | V35: =A35-A34 -> 9
A36: 46096 | B36: BYD Atto3 | C36: 5407 | D36: 0.28 | E36: 0.45 | F36: =E36-D36 -> 0.17 | G36: =F36*VLOOKUP(B36,EVs!$A$2:$E$5,2,false) -> 10.285 | H36: 6.1 Kw | I36: =G36/left(H36,3) -> 1.6860656 | J36: 46096.319 | K36: =J36+I36/24 -> 46096.389 | L36: 46096.39 | M36: 0.45 | N36: =M36-D36 -> 0.17 | O36: =N36*VLOOKUP(B36,EVs!$A$2:$E$5,2,false) -> 10.285 | P36: =(L36-J36)*24 -> 1.7 | Q36: =N36*VLOOKUP(B36,EVs!$A$2:$E$5,2,false)/P36 -> 6.05 | R36: Garage | S36: =O36*15 -> 154.275 | T36: =(C36-C35)/((M35-D36)*60.5) -> 6.2322179 | U36: =C36-C35 -> 230 | V36: =A36-A35 -> 4
A37: 46096 | B37: BYD Atto3 | C37: 5436 | D37: 0.37 | E37: 1 | F37: =E37-D37 -> 0.63 | G37: =F37*VLOOKUP(B37,EVs!$A$2:$E$5,2,false) -> 38.115 | H37: 6.1 Kw | I37: =G37/left(H37,3) -> 6.2483607 | J37: 46096.658 | K37: =J37+I37/24 -> 46096.919 | L37: 46096.907 | M37: 1 | N37: =M37-D37 -> 0.63 | O37: =N37*VLOOKUP(B37,EVs!$A$2:$E$5,2,false) -> 38.115 | P37: =(L37-J37)*24 -> 5.9666667 | Q37: =N37*VLOOKUP(B37,EVs!$A$2:$E$5,2,false)/P37 -> 6.3879888 | R37: Garage | S37: =O37*15 -> 571.725 | T37: =(C37-C36)/((M36-D37)*60.5) -> 5.9917355 | U37: =C37-C36 -> 29 | V37: =A37-A36 -> 0
A38: 46101 | B38: BYD Atto3 | C38: 5533 | D38: 0.73 | E38: 0.86 | F38: =E38-D38 -> 0.13 | G38: =F38*VLOOKUP(B38,EVs!$A$2:$E$5,2,false) -> 7.865 | H38: 6.1 Kw | I38: =G38/left(H38,3) -> 1.2893443 | J38: 46101.396 | K38: =J38+I38/24 -> 46101.45 | L38: 46101.457 | M38: 0.86 | N38: =M38-D38 -> 0.13 | O38: =N38*VLOOKUP(B38,EVs!$A$2:$E$5,2,false) -> 7.865 | P38: =(L38-J38)*24 -> 1.4666667 | Q38: =N38*VLOOKUP(B38,EVs!$A$2:$E$5,2,false)/P38 -> 5.3625 | R38: Garage | S38: =O38*15 -> 117.975 | T38: =(C38-C37)/((M37-D38)*60.5) -> 5.9381696 | U38: =C38-C37 -> 97 | V38: =A38-A37 -> 5
A39: 46101 | B39: BYD Atto3 | C39: 5706 | D39: 0.41 | E39: 0.53 | F39: =E39-D39 -> 0.12 | G39: =F39*VLOOKUP(B39,EVs!$A$2:$E$5,2,false) -> 7.26 | H39: 6.1 Kw | I39: =G39/left(H39,3) -> 1.1901639 | J39: 46101.712 | K39: =J39+I39/24 -> 46101.761 | L39: 46101.764 | M39: 0.53 | N39: =M39-D39 -> 0.12 | O39: =N39*VLOOKUP(B39,EVs!$A$2:$E$5,2,false) -> 7.26 | P39: =(L39-J39)*24 -> 1.25 | Q39: =N39*VLOOKUP(B39,EVs!$A$2:$E$5,2,false)/P39 -> 5.808 | R39: Garage | S39: =O39*15 -> 108.9 | T39: =(C39-C38)/((M38-D39)*60.5) -> 6.3544536 | U39: =C39-C38 -> 173 | V39: =A39-A38 -> 0 | W39: trip to
A40: 46101 | B40: BYD Atto3 | C40: 5838 | D40: 0.19 | E40: 0.85 | F40: =E40-D40 -> 0.66 | G40: =F40*VLOOKUP(B40,EVs!$A$2:$E$5,2,false) -> 39.93 | H40: 6.1 Kw | I40: =G40/left(H40,3) -> 6.5459016 | J40: 46101.894 | K40: =J40+I40/24 -> 46102.166 | L40: 46102.167 | M40: 0.85 | N40: =M40-D40 -> 0.66 | O40: =N40*VLOOKUP(B40,EVs!$A$2:$E$5,2,false) -> 39.93 | P40: =(L40-J40)*24 -> 6.55 | Q40: =N40*VLOOKUP(B40,EVs!$A$2:$E$5,2,false)/P40 -> 6.0961832 | R40: Garage | S40: =O40*15 -> 598.95 | T40: =(C40-C39)/((M39-D40)*60.5) -> 6.4171123 | U40: =C40-C39 -> 132 | V40: =A40-A39 -> 0 | W40: Paniqui, Tarlac
...

Sheet EVs
A1: Car Model | B1: Capacity | C1: Units | D1: Range | E1: Km
A2: BYD Atto3 | B2: 60.5 | C2: KwH | D2: =B2*7.9 -> 477.95 | E2: km
A3: BYD Seal Advance
A4: Tesla Model Y
A5: Tesla Model 3
